<?xml version="1.0" ?>
<!-- =================================================================================== -->
<!-- |    This document was autogenerated by xacro from kmr.xacro                      | -->
<!-- |    EDITING THIS FILE BY HAND IS NOT RECOMMENDED                                 | -->
<!-- =================================================================================== -->
<robot name="kmr">
  <!-- Based of https://github.com/stoic-roboticist/kmriiwa_ros_stack -->
  <material name="Black">
    <color rgba="0.0 0.0 0.0 1.0"/>
  </material>
  <material name="Blue">
    <color rgba="0.0 0.0 0.8 1.0"/>
  </material>
  <material name="Green">
    <color rgba="0.0 0.8 0.0 1.0"/>
  </material>
  <material name="Grey">
    <color rgba="0.4 0.4 0.4 1.0"/>
  </material>
  <material name="DarkGrey">
    <color rgba="0.3 0.3 0.3 1.0"/>
  </material>
  <material name="Orange">
    <color rgba="1.0 0.4235294117647059 0.0392156862745098 1.0"/>
  </material>
  <material name="Brown">
    <color rgba="0.8705882352941177 0.8117647058823529 0.7647058823529411 1.0"/>
  </material>
  <material name="Red">
    <color rgba="0.8 0.0 0.0 1.0"/>
  </material>
  <material name="White">
    <color rgba="1.0 1.0 1.0 1.0"/>
  </material>
  <material name="aluminum">
    <color rgba="0.5 0.5 0.5 1"/>
  </material>
  <!-- From https://github.com/stoic-roboticist/kmriiwa_ros_stack -->
  <!-- From https://github.com/stoic-roboticist/kmriiwa_ros_stack -->
  <!-- distance from wheel-floor contact point to base bottom side-->
  <!-- Aluminum material is commentet out as it is defined elsewhere and
  it causes conflicts if not commented out -->
  <!-- <material name="aluminum">
    <color rgba="0.5 0.5 0.5 1"/>
  </material> -->
  <material name="plastic">
    <color rgba="0.1 0.1 0.1 1"/>
  </material>
  <!-- 
  The shape and size of the adapter is based on Heggem & Wahl's urdf-descriptions of the KMR found at 
  https://github.com/ninamwa/kmriiwa_ws/blob/eloquent/kmr_bringup/urdf/kmriiwa_withcameraframes.urdf
-->
  <!-- 
  The shape and size of the adapter is based on Heggem & Wahl's urdf-descriptions of the KMR found at 
  https://github.com/ninamwa/kmriiwa_ws/blob/eloquent/kmr_bringup/urdf/kmriiwa.urdf
-->
  <link name="kmr_base_footprint"/>
  <joint name="kmr_footprint_to_base_link" type="fixed">
    <parent link="kmr_base_footprint"/>
    <child link="kmr_base_link"/>
    <origin rpy="0 0 0.0" xyz="0 0 0.025"/>
  </joint>
  <link name="kmr_base_link">
    <origin rpy="0 0 0" xyz="0 0 0"/>
    <visual>
      <geometry>
        <mesh filename="package://kmr_description/meshes/kmp200/KMP200.dae"/>
      </geometry>
      <material name="White"/>
    </visual>
    <collision>
      <geometry>
        <mesh filename="package://kmr_description/meshes/kmp200/KMP200.dae"/>
      </geometry>
    </collision>
    <inertial>
      <origin rpy="0 0 0" xyz="0 0 0.23500000000000001"/>
      <mass value="390"/>
      <!-- obtained from KMP200 model on fusion 360 with some modification to align center of mass with the given one-->
      <inertia ixx="28.95" ixy="0.0" ixz="0.0" iyy="44.03" iyz="0.0" izz="33.83"/>
    </inertial>
  </link>
  <joint name="kmr_base_link_to_top" type="fixed">
    <parent link="kmr_base_link"/>
    <child link="kmr_base_top_link"/>
    <origin rpy="0 0 0.0" xyz="0 0 0.6749999999999999"/>
  </joint>
  <link name="kmr_base_top_link"/>
  <joint name="kmr_laser_B1_joint" type="fixed">
    <parent link="kmr_base_link"/>
    <child link="kmr_laser_B1_link"/>
    <origin rpy="0 0 -0.7854" xyz="0.464 -0.256 0.1168"/>
  </joint>
  <link name="kmr_laser_B1_link">
    <visual>
      <origin rpy="3.1413 0 0" xyz="0 0 0"/>
      <geometry>
        <mesh filename="package://kmr_description/meshes/kmp200/sensors/visual/sick_lms1xx.dae"/>
      </geometry>
      <material name="DarkGrey"/>
    </visual>
    <collision>
      <origin rpy="0 0 0" xyz="0.0 0 0.0"/>
      <geometry>
        <mesh filename="package://kmr_description/meshes/kmp200/sensors/collision/sick_lms1xx.stl"/>
      </geometry>
    </collision>
    <inertial>
      <mass value="1.2"/>
      <inertia ixx="0.002355" ixy="0.0" ixz="0.0" iyy="0.002355" iyz="0.0" izz="0.0002809"/>
    </inertial>
  </link>
  <joint name="kmr_laser_B4_joint" type="fixed">
    <parent link="kmr_base_link"/>
    <child link="kmr_laser_B4_link"/>
    <origin rpy="0 0 2.3562" xyz="-0.464 0.256 0.1168"/>
  </joint>
  <link name="kmr_laser_B4_link">
    <visual>
      <origin rpy="0 3.1413 3.1413" xyz="0.0 0 0"/>
      <geometry>
        <mesh filename="package://kmr_description/meshes/kmp200/sensors/visual/sick_lms1xx.dae"/>
      </geometry>
      <material name="DarkGrey"/>
    </visual>
    <collision>
      <origin rpy="0 0 0" xyz="0 0 0"/>
      <geometry>
        <mesh filename="package://kmr_description/meshes/kmp200/sensors/collision/sick_lms1xx.stl"/>
      </geometry>
    </collision>
    <inertial>
      <mass value="1.2"/>
      <inertia ixx="0.002355" ixy="0.0" ixz="0.0" iyy="0.002355" iyz="0.0" izz="0.0002809"/>
    </inertial>
  </link>
  <link name="kmr_front_left_wheel_link">
    <visual>
      <origin rpy="0 0 0" xyz="0 0 0"/>
      <geometry>
        <mesh filename="package://kmr_description/meshes/kmp200/wheels/omni_wheel_1.dae" scale="1.06695 1.06695 1.06695"/>
      </geometry>
    </visual>
    <collision>
      <origin rpy="1.57 0 0" xyz="0 0 0"/>
      <geometry>
        <cylinder length="0.132" radius="0.125"/>
      </geometry>
    </collision>
  </link>
  <link name="kmr_front_right_wheel_link">
    <visual>
      <origin rpy="0 0 0" xyz="0 0 0"/>
      <geometry>
        <mesh filename="package://kmr_description/meshes/kmp200/wheels/omni_wheel_1.dae" scale="1.06695 1.06695 1.06695"/>
      </geometry>
    </visual>
    <collision>
      <origin rpy="1.57 0 0" xyz="0 0 0"/>
      <geometry>
        <cylinder length="0.132" radius="0.125"/>
      </geometry>
    </collision>
  </link>
  <link name="kmr_back_left_wheel_link">
    <visual>
      <origin rpy="0 0 0" xyz="0 0 0"/>
      <geometry>
        <mesh filename="package://kmr_description/meshes/kmp200/wheels/omni_wheel_1.dae" scale="1.06695 1.06695 1.06695"/>
      </geometry>
    </visual>
    <collision>
      <origin rpy="1.57 0 0" xyz="0 0 0"/>
      <geometry>
        <cylinder length="0.132" radius="0.125"/>
      </geometry>
    </collision>
  </link>
  <link name="kmr_back_right_wheel_link">
    <visual>
      <origin rpy="0 0 0" xyz="0 0 0"/>
      <geometry>
        <mesh filename="package://kmr_description/meshes/kmp200/wheels/omni_wheel_1.dae" scale="1.06695 1.06695 1.06695"/>
      </geometry>
    </visual>
    <collision>
      <origin rpy="1.57 0 0" xyz="0 0 0"/>
      <geometry>
        <cylinder length="0.132" radius="0.125"/>
      </geometry>
    </collision>
    <!-- <inertial>
            <mass value="14"/>
            <inertia ixx="0.075016" ixy="0.0" ixz="0.0" iyy="0.075016" iyz="0.0" izz="0.109375"/>
        </inertial> -->
  </link>
  <joint name="kmr_front_left_wheel_joint" type="continuous">
    <parent link="kmr_base_link"/>
    <child link="kmr_front_left_wheel_link"/>
    <axis xyz="0 1 0"/>
    <origin xyz="0.28 0.1825 0.1"/>
    <limit effort="100" velocity="100"/>
    <joint_properties damping="0.0" friction="0.0"/>
  </joint>
  <joint name="kmr_front_right_wheel_joint" type="continuous">
    <parent link="kmr_base_link"/>
    <child link="kmr_front_right_wheel_link"/>
    <origin xyz="0.28 -0.1825 0.1"/>
    <axis xyz="0 1 0"/>
    <limit effort="100" velocity="100"/>
    <joint_properties damping="0.0" friction="0.0"/>
  </joint>
  <joint name="kmr_back_left_wheel_joint" type="continuous">
    <parent link="kmr_base_link"/>
    <child link="kmr_back_left_wheel_link"/>
    <origin xyz="-0.28 0.1825 0.1"/>
    <axis xyz="0 1 0"/>
    <limit effort="100" velocity="100"/>
    <joint_properties damping="0.0" friction="0.0"/>
  </joint>
  <joint name="kmr_back_right_wheel_joint" type="continuous">
    <parent link="kmr_base_link"/>
    <child link="kmr_back_right_wheel_link"/>
    <origin xyz="-0.28 -0.1825 0.1"/>
    <axis xyz="0 1 0"/>
    <limit effort="100" velocity="100"/>
    <joint_properties damping="0.0" friction="0.0"/>
  </joint>
  <!-- Gazebo planar move plugin -->
  <!-- <gazebo>
        <plugin name='planar_move' filename='libgazebo_ros_planar_move.so'>
            <robotNamespace>/${robot_name}</robotNamespace>
            <commandTopic>base/command/cmd_vel</commandTopic>
            <odometryTopic>base/state/odom</odometryTopic>
            <update_rate>100</update_rate>
            <publish_rate>10</publish_rate>

            
            <publish_odom>true</publish_odom>
            <publish_odom_tf>true</publish_odom_tf>

            <odometryFrame>odom</odometryFrame>
            <robotBaseFrame>base_link</robotBaseFrame>
            <odometryRate>20.0</odometryRate>

            <covariance_x>0.0001</covariance_x>
            <covariance_y>0.0001</covariance_y>
            <covariance_yaw>0.01</covariance_yaw>
        </plugin>
    </gazebo>  -->
  <!-- Hector ros force based planar move plugin -->
  <gazebo>
    <plugin filename="libgazebo_ros_force_based_move.so" name="ros_force_based_move">
      <robotNamespace>/kmr</robotNamespace>
      <commandTopic>base/command/cmd_vel</commandTopic>
      <odometryTopic>base/state/odom</odometryTopic>
      <robotBaseFrame>kmr_base_footprint</robotBaseFrame>
      <publishOdometryTf>true</publishOdometryTf>
      <odometryFrame>kmr_odom</odometryFrame>
      <odometryRate>20.0</odometryRate>
      <yaw_velocity_p_gain>500</yaw_velocity_p_gain>
      <x_velocity_p_gain>1000</x_velocity_p_gain>
      <y_velocity_p_gain>1000</y_velocity_p_gain>
    </plugin>
  </gazebo>
  <gazebo reference="kmr_laser_B1_link">
    <sensor name="sensor_B1" type="ray">
      <always_on>true</always_on>
      <visualize>true</visualize>
      <update_rate>10</update_rate>
      <ray>
        <scan>
          <horizontal>
            <samples>640</samples>
            <resolution>1.000000</resolution>
            <min_angle>-2.30383</min_angle>
            <max_angle>2.30383</max_angle>
          </horizontal>
        </scan>
        <range>
          <min>0.12</min>
          <max>15</max>
          <resolution>0.0100</resolution>
        </range>
        <noise>
          <type>gaussian</type>
          <mean>0.0</mean>
          <stddev>0.01</stddev>
        </noise>
      </ray>
      <plugin filename="libgazebo_ros_laser.so" name="gazebo_sensor_B1_controller">
        <robotNamespace>/</robotNamespace>
        <topicName>/kmr/base/state/LaserB1Scan</topicName>
        <output_type>sensor_msgs/LaserScan</output_type>
        <frameName>kmr_laser_B1_link</frameName>
      </plugin>
    </sensor>
  </gazebo>
  <gazebo reference="kmr_laser_B4_link">
    <sensor name="sensor_B4" type="ray">
      <always_on>true</always_on>
      <visualize>true</visualize>
      <update_rate>10</update_rate>
      <ray>
        <scan>
          <horizontal>
            <samples>640</samples>
            <resolution>1.000000</resolution>
            <min_angle>-2.30383</min_angle>
            <max_angle>2.30383</max_angle>
          </horizontal>
        </scan>
        <range>
          <min>0.12</min>
          <max>15</max>
          <resolution>0.0100</resolution>
        </range>
        <noise>
          <type>gaussian</type>
          <mean>0.0</mean>
          <stddev>0.01</stddev>
        </noise>
      </ray>
      <plugin filename="libgazebo_ros_laser.so" name="gazebo_sensor_B4_controller">
        <robotNamespace>/</robotNamespace>
        <topicName>/kmr/base/state/LaserB4Scan</topicName>
        <output_type>sensor_msgs/LaserScan</output_type>
        <frameName>kmr_laser_B4_link</frameName>
      </plugin>
    </sensor>
  </gazebo>
  <gazebo reference="kmr_base_link">
    <material>Gazebo/Grey</material>
  </gazebo>
  <gazebo reference="kmr_front_left_wheel_link">
    <mu1 value="0.0"/>
    <mu2 value="0.0"/>
    <surface>
      <contact>
        <collide_without_contact>true</collide_without_contact>
      </contact>
    </surface>
  </gazebo>
  <gazebo reference="kmr_front_right_wheel_link">
    <mu1 value="0.0"/>
    <mu2 value="0.0"/>
    <surface>
      <contact>
        <collide_without_contact>true</collide_without_contact>
      </contact>
    </surface>
  </gazebo>
  <gazebo reference="kmr_back_left_wheel_link">
    <mu1 value="0.0"/>
    <mu2 value="0.0"/>
    <surface>
      <contact>
        <collide_without_contact>true</collide_without_contact>
      </contact>
    </surface>
  </gazebo>
  <gazebo reference="kmr_back_right_wheel_link">
    <mu1 value="0.0"/>
    <mu2 value="0.0"/>
    <surface>
      <contact>
        <collide_without_contact>true</collide_without_contact>
      </contact>
    </surface>
  </gazebo>
  <!--riser flange-->
  <joint name="kmr_base_top_riser_flange_joint" type="fixed">
    <parent link="kmr_base_top_link"/>
    <child link="kmr_riser_flange_link"/>
    <origin rpy="0 0 -1.5708" xyz="0.363 -0.184 -0.01"/>
  </joint>
  <link name="kmr_riser_flange_link">
    <visual>
      <origin rpy="0 0 0" xyz="0 0 0"/>
      <geometry>
        <cylinder length="0.0" radius="0.121"/>
      </geometry>
      <material name="White"/>
    </visual>
    <collision>
      <origin rpy="0 0 0" xyz="0 0 0"/>
      <geometry>
        <cylinder length="0.0" radius="0.121"/>
      </geometry>
    </collision>
  </link>
  <!--joint between {parent} and link_0-->
  <joint name="kmr_riser_flange_link_kmr_joint" type="fixed">
    <origin rpy="0 0 0" xyz="0 0 0.0"/>
    <parent link="kmr_riser_flange_link"/>
    <child link="kmr_link_0"/>
  </joint>
  <link name="kmr_link_0">
    <inertial>
      <origin rpy="0 0 0" xyz="0.0 0.0 0.0"/>
      <mass value="5"/>
      <inertia ixx="0.05" ixy="0" ixz="0" iyy="0.06" iyz="0" izz="0.03"/>
    </inertial>
    <visual>
      <origin rpy="0 0 0" xyz="0 0 0"/>
      <geometry>
        <mesh filename="package://kmr_description/meshes/iiwa14/visual/link_0.stl"/>
      </geometry>
      <material name="Grey"/>
    </visual>
    <collision>
      <origin rpy="0 0 0" xyz="0 0 0"/>
      <geometry>
        <mesh filename="package://kmr_description/meshes/iiwa14/collision/link_0.stl"/>
      </geometry>
      <material name="Grey"/>
    </collision>
    <self_collision_checking>
      <origin rpy="0 0 0" xyz="0 0 0"/>
      <geometry>
        <capsule length="0.25" radius="0.15"/>
      </geometry>
    </self_collision_checking>
  </link>
  <!-- joint between link_0 and link_1 -->
  <joint name="kmr_joint_1" type="revolute">
    <parent link="kmr_link_0"/>
    <child link="kmr_link_1"/>
    <origin rpy="0 0 0" xyz="0 0 0.1575"/>
    <axis xyz="0 0 1"/>
    <limit effort="300" lower="-2.9670597283903604" upper="2.9670597283903604" velocity="10"/>
    <safety_controller k_position="100" k_velocity="2" soft_lower_limit="-2.9321531433504737" soft_upper_limit="2.9321531433504737"/>
    <dynamics damping="0.5"/>
  </joint>
  <link name="kmr_link_1">
    <inertial>
      <origin rpy="0 0 0" xyz="0 -0.03 0.12"/>
      <mass value="4"/>
      <inertia ixx="0.1" ixy="0" ixz="0" iyy="0.09" iyz="0" izz="0.02"/>
    </inertial>
    <visual>
      <origin rpy="0 0 0" xyz="0 0 0"/>
      <geometry>
        <mesh filename="package://kmr_description/meshes/iiwa14/visual/link_1.stl"/>
      </geometry>
      <material name="Orange"/>
    </visual>
    <collision>
      <origin rpy="0 0 0" xyz="0 0 0"/>
      <geometry>
        <mesh filename="package://kmr_description/meshes/iiwa14/collision/link_1.stl"/>
      </geometry>
      <material name="Orange"/>
    </collision>
  </link>
  <!-- joint between link_1 and link_2 -->
  <joint name="kmr_joint_2" type="revolute">
    <parent link="kmr_link_1"/>
    <child link="kmr_link_2"/>
    <origin rpy="1.5707963267948966   0 3.141592653589793" xyz="0 0 0.2025"/>
    <axis xyz="0 0 1"/>
    <limit effort="300" lower="-2.0943951023931953" upper="2.0943951023931953" velocity="10"/>
    <safety_controller k_position="100" k_velocity="2" soft_lower_limit="-2.0594885173533086" soft_upper_limit="2.0594885173533086"/>
    <dynamics damping="0.5"/>
  </joint>
  <link name="kmr_link_2">
    <inertial>
      <origin rpy="0 0 0" xyz="0.0003 0.059 0.042"/>
      <mass value="4"/>
      <inertia ixx="0.05" ixy="0" ixz="0" iyy="0.018" iyz="0" izz="0.044"/>
    </inertial>
    <visual>
      <origin rpy="0 0 0" xyz="0 0 0"/>
      <geometry>
        <mesh filename="package://kmr_description/meshes/iiwa14/visual/link_2.stl"/>
      </geometry>
      <material name="Orange"/>
    </visual>
    <collision>
      <origin rpy="0 0 0" xyz="0 0 0"/>
      <geometry>
        <mesh filename="package://kmr_description/meshes/iiwa14/collision/link_2.stl"/>
      </geometry>
      <material name="Orange"/>
    </collision>
  </link>
  <!-- joint between link_2 and link_3 -->
  <joint name="kmr_joint_3" type="revolute">
    <parent link="kmr_link_2"/>
    <child link="kmr_link_3"/>
    <origin rpy="1.5707963267948966 0 3.141592653589793" xyz="0 0.2045 0"/>
    <axis xyz="0 0 1"/>
    <limit effort="300" lower="-2.9670597283903604" upper="2.9670597283903604" velocity="10"/>
    <safety_controller k_position="100" k_velocity="2" soft_lower_limit="-2.9321531433504737" soft_upper_limit="2.9321531433504737"/>
    <dynamics damping="0.5"/>
  </joint>
  <link name="kmr_link_3">
    <inertial>
      <origin rpy="0 0 0" xyz="0 0.03 0.13"/>
      <mass value="3"/>
      <inertia ixx="0.08" ixy="0" ixz="0" iyy="0.075" iyz="0" izz="0.01"/>
    </inertial>
    <visual>
      <origin rpy="0 0 0" xyz="0 0 0"/>
      <geometry>
        <mesh filename="package://kmr_description/meshes/iiwa14/visual/link_3.stl"/>
      </geometry>
      <material name="Orange"/>
    </visual>
    <collision>
      <origin rpy="0 0 0" xyz="0 0 0"/>
      <geometry>
        <mesh filename="package://kmr_description/meshes/iiwa14/collision/link_3.stl"/>
      </geometry>
      <material name="Orange"/>
    </collision>
  </link>
  <!-- joint between link_3 and link_4 -->
  <joint name="kmr_joint_4" type="revolute">
    <parent link="kmr_link_3"/>
    <child link="kmr_link_4"/>
    <origin rpy="1.5707963267948966 0 0" xyz="0 0 0.2155"/>
    <axis xyz="0 0 1"/>
    <limit effort="300" lower="-2.0943951023931953" upper="2.0943951023931953" velocity="10"/>
    <safety_controller k_position="100" k_velocity="2" soft_lower_limit="-2.0594885173533086" soft_upper_limit="2.0594885173533086"/>
    <dynamics damping="0.5"/>
  </joint>
  <link name="kmr_link_4">
    <inertial>
      <origin rpy="0 0 0" xyz="0 0.067 0.034"/>
      <mass value="2.7"/>
      <inertia ixx="0.03" ixy="0" ixz="0" iyy="0.01" iyz="0" izz="0.029"/>
    </inertial>
    <visual>
      <origin rpy="0 0 0" xyz="0 0 0"/>
      <geometry>
        <mesh filename="package://kmr_description/meshes/iiwa14/visual/link_4.stl"/>
      </geometry>
      <material name="Orange"/>
    </visual>
    <collision>
      <origin rpy="0 0 0" xyz="0 0 0"/>
      <geometry>
        <mesh filename="package://kmr_description/meshes/iiwa14/collision/link_4.stl"/>
      </geometry>
      <material name="Orange"/>
    </collision>
  </link>
  <!-- joint between link_4 and link_5 -->
  <joint name="kmr_joint_5" type="revolute">
    <parent link="kmr_link_4"/>
    <child link="kmr_link_5"/>
    <origin rpy="-1.5707963267948966 3.141592653589793 0" xyz="0 0.1845 0"/>
    <axis xyz="0 0 1"/>
    <limit effort="300" lower="-2.9670597283903604" upper="2.9670597283903604" velocity="10"/>
    <safety_controller k_position="100" k_velocity="2" soft_lower_limit="-2.9321531433504737" soft_upper_limit="2.9321531433504737"/>
    <dynamics damping="0.5"/>
  </joint>
  <link name="kmr_link_5">
    <inertial>
      <origin rpy="0 0 0" xyz="0.0001 0.021 0.076"/>
      <mass value="1.7"/>
      <inertia ixx="0.02" ixy="0" ixz="0" iyy="0.018" iyz="0" izz="0.005"/>
    </inertial>
    <visual>
      <origin rpy="0 0 0" xyz="0 0 0"/>
      <geometry>
        <mesh filename="package://kmr_description/meshes/iiwa14/visual/link_5.stl"/>
      </geometry>
      <material name="Orange"/>
    </visual>
    <collision>
      <origin rpy="0 0 0" xyz="0 0 0"/>
      <geometry>
        <mesh filename="package://kmr_description/meshes/iiwa14/collision/link_5.stl"/>
      </geometry>
      <material name="Orange"/>
    </collision>
  </link>
  <!-- joint between link_5 and link_6 -->
  <joint name="kmr_joint_6" type="revolute">
    <parent link="kmr_link_5"/>
    <child link="kmr_link_6"/>
    <origin rpy="1.5707963267948966 0 0" xyz="0 0 0.2155"/>
    <axis xyz="0 0 1"/>
    <limit effort="300" lower="-2.0943951023931953" upper="2.0943951023931953" velocity="10"/>
    <safety_controller k_position="100" k_velocity="2" soft_lower_limit="-2.0594885173533086" soft_upper_limit="2.0594885173533086"/>
    <dynamics damping="0.5"/>
  </joint>
  <link name="kmr_link_6">
    <inertial>
      <origin rpy="0 0 0" xyz="0 0.0006 0.0004"/>
      <mass value="1.8"/>
      <inertia ixx="0.005" ixy="0" ixz="0" iyy="0.0036" iyz="0" izz="0.0047"/>
    </inertial>
    <visual>
      <origin rpy="0 0 0" xyz="0 0 0"/>
      <geometry>
        <mesh filename="package://kmr_description/meshes/iiwa14/visual/link_6.stl"/>
      </geometry>
      <material name="Orange"/>
    </visual>
    <collision>
      <origin rpy="0 0 0" xyz="0 0 0"/>
      <geometry>
        <mesh filename="package://kmr_description/meshes/iiwa14/collision/link_6.stl"/>
      </geometry>
      <material name="Orange"/>
    </collision>
  </link>
  <!-- joint between link_6 and link_7 -->
  <joint name="kmr_joint_7" type="revolute">
    <parent link="kmr_link_6"/>
    <child link="kmr_link_7"/>
    <origin rpy="-1.5707963267948966 3.141592653589793 0" xyz="0 0.081 0"/>
    <axis xyz="0 0 1"/>
    <limit effort="300" lower="-3.0543261909900763" upper="3.0543261909900763" velocity="10"/>
    <safety_controller k_position="100" k_velocity="2" soft_lower_limit="-3.01941960595019" soft_upper_limit="3.01941960595019"/>
    <dynamics damping="0.5"/>
  </joint>
  <link name="kmr_link_7">
    <inertial>
      <origin rpy="0 0 0" xyz="0 0 0.02"/>
      <mass value="0.3"/>
      <inertia ixx="0.001" ixy="0" ixz="0" iyy="0.001" iyz="0" izz="0.001"/>
    </inertial>
    <visual>
      <origin rpy="0 0 0" xyz="0 0 0"/>
      <geometry>
        <mesh filename="package://kmr_description/meshes/iiwa14/visual/link_7.stl"/>
      </geometry>
      <material name="Grey"/>
    </visual>
    <collision>
      <origin rpy="0 0 0" xyz="0 0 0"/>
      <geometry>
        <mesh filename="package://kmr_description/meshes/iiwa14/collision/link_7.stl"/>
      </geometry>
      <material name="Grey"/>
    </collision>
  </link>
  <joint name="kmr_joint_ee" type="fixed">
    <parent link="kmr_link_7"/>
    <child link="kmr_link_ee"/>
    <origin rpy="0 0 0" xyz="0 0 0.045"/>
  </joint>
  <link name="kmr_link_ee">
    </link>
  <!-- Enable the Joint Feedback -->
  <gazebo reference="kmr_joint_7">
    <provideFeedback>true</provideFeedback>
  </gazebo>
  <!-- The ft_sensor plugin -->
  <gazebo>
    <plugin filename="libgazebo_ros_ft_sensor.so" name="ft_sensor">
      <updateRate>50.0</updateRate>
      <topicName>/kmr/state/CartesianWrench</topicName>
      <jointName>kmr_joint_7</jointName>
    </plugin>
  </gazebo>
  <!-- Load Gazebo lib and set the robot namespace -->
  <gazebo>
    <plugin filename="libgazebo_ros_control.so" name="gazebo_ros_control">
      <robotNamespace>/kmr/arm</robotNamespace>
      <robotParam>/kmr/robot_description</robotParam>
    </plugin>
  </gazebo>
  <!-- Link0 -->
  <gazebo reference="kmr_link_0">
    <material>Gazebo/Grey</material>
    <mu1>0.2</mu1>
    <mu2>0.2</mu2>
  </gazebo>
  <!-- Link1 -->
  <gazebo reference="kmr_link_1">
    <material>Gazebo/Orange</material>
    <mu1>0.2</mu1>
    <mu2>0.2</mu2>
  </gazebo>
  <!-- Link2 -->
  <gazebo reference="kmr_link_2">
    <material>Gazebo/Orange</material>
    <mu1>0.2</mu1>
    <mu2>0.2</mu2>
  </gazebo>
  <!-- Link3 -->
  <gazebo reference="kmr_link_3">
    <material>Gazebo/Orange</material>
    <mu1>0.2</mu1>
    <mu2>0.2</mu2>
  </gazebo>
  <!-- Link4 -->
  <gazebo reference="kmr_link_4">
    <material>Gazebo/Orange</material>
    <mu1>0.2</mu1>
    <mu2>0.2</mu2>
  </gazebo>
  <!-- Link5 -->
  <gazebo reference="kmr_link_5">
    <material>Gazebo/Orange</material>
    <mu1>0.2</mu1>
    <mu2>0.2</mu2>
  </gazebo>
  <!-- Link6 -->
  <gazebo reference="kmr_link_6">
    <material>Gazebo/Orange</material>
    <mu1>0.2</mu1>
    <mu2>0.2</mu2>
  </gazebo>
  <!-- Link7 -->
  <gazebo reference="kmr_link_7">
    <material>Gazebo/Grey</material>
    <mu1>0.2</mu1>
    <mu2>0.2</mu2>
  </gazebo>
  <transmission name="kmr_tran_1">
    <robotNamespace>/kmr/arm</robotNamespace>
    <type>transmission_interface/SimpleTransmission</type>
    <joint name="kmr_joint_1">
      <hardwareInterface>hardware_interface/PositionJointInterface</hardwareInterface>
    </joint>
    <actuator name="kmr_motor_1">
      <hardwareInterface>hardware_interface/PositionJointInterface</hardwareInterface>
      <mechanicalReduction>1</mechanicalReduction>
    </actuator>
  </transmission>
  <transmission name="kmr_tran_2">
    <robotNamespace>/kmr/arm</robotNamespace>
    <type>transmission_interface/SimpleTransmission</type>
    <joint name="kmr_joint_2">
      <hardwareInterface>hardware_interface/PositionJointInterface</hardwareInterface>
    </joint>
    <actuator name="kmr_motor_2">
      <hardwareInterface>hardware_interface/PositionJointInterface</hardwareInterface>
      <mechanicalReduction>1</mechanicalReduction>
    </actuator>
  </transmission>
  <transmission name="kmr_tran_3">
    <robotNamespace>/kmr/arm</robotNamespace>
    <type>transmission_interface/SimpleTransmission</type>
    <joint name="kmr_joint_3">
      <hardwareInterface>hardware_interface/PositionJointInterface</hardwareInterface>
    </joint>
    <actuator name="kmr_motor_3">
      <hardwareInterface>hardware_interface/PositionJointInterface</hardwareInterface>
      <mechanicalReduction>1</mechanicalReduction>
    </actuator>
  </transmission>
  <transmission name="kmr_tran_4">
    <robotNamespace>/kmr/arm</robotNamespace>
    <type>transmission_interface/SimpleTransmission</type>
    <joint name="kmr_joint_4">
      <hardwareInterface>hardware_interface/PositionJointInterface</hardwareInterface>
    </joint>
    <actuator name="kmr_motor_4">
      <hardwareInterface>hardware_interface/PositionJointInterface</hardwareInterface>
      <mechanicalReduction>1</mechanicalReduction>
    </actuator>
  </transmission>
  <transmission name="kmr_tran_5">
    <robotNamespace>/kmr/arm</robotNamespace>
    <type>transmission_interface/SimpleTransmission</type>
    <joint name="kmr_joint_5">
      <hardwareInterface>hardware_interface/PositionJointInterface</hardwareInterface>
    </joint>
    <actuator name="kmr_motor_5">
      <hardwareInterface>hardware_interface/PositionJointInterface</hardwareInterface>
      <mechanicalReduction>1</mechanicalReduction>
    </actuator>
  </transmission>
  <transmission name="kmr_tran_6">
    <robotNamespace>/kmr/arm</robotNamespace>
    <type>transmission_interface/SimpleTransmission</type>
    <joint name="kmr_joint_6">
      <hardwareInterface>hardware_interface/PositionJointInterface</hardwareInterface>
    </joint>
    <actuator name="kmr_motor_6">
      <hardwareInterface>hardware_interface/PositionJointInterface</hardwareInterface>
      <mechanicalReduction>1</mechanicalReduction>
    </actuator>
  </transmission>
  <transmission name="kmr_tran_7">
    <robotNamespace>/kmr/arm</robotNamespace>
    <type>transmission_interface/SimpleTransmission</type>
    <joint name="kmr_joint_7">
      <hardwareInterface>hardware_interface/PositionJointInterface</hardwareInterface>
    </joint>
    <actuator name="kmr_motor_7">
      <hardwareInterface>hardware_interface/PositionJointInterface</hardwareInterface>
      <mechanicalReduction>1</mechanicalReduction>
    </actuator>
  </transmission>
  <joint name="joint_a7_adapter" type="fixed">
    <origin rpy="0 0 0" xyz="0 0 0.005"/>
    <parent link="kmr_link_ee"/>
    <child link="gripper_adapter"/>
  </joint>
  <link name="gripper_adapter">
    <visual>
      <origin rpy="0 0 0" xyz="0 0 0"/>
      <geometry>
        <cylinder length="0.01" radius="0.0375"/>
      </geometry>
      <material name="aluminum"/>
    </visual>
  </link>
  <!--joint between {parent} and link_ee-->
  <joint name="gripper_adapter_joint_gripper" type="fixed">
    <origin rpy="0 0 0" xyz="0 0 0.005"/>
    <parent link="gripper_adapter"/>
    <child link="gripper_base_link"/>
  </joint>
  <link name="gripper_base_link">
    <inertial>
      <origin rpy="0 0 0" xyz="0.00021987 -2.3546E-10 0.030163"/>
      <mass value="0.30915"/>
      <inertia ixx="0.00028972" ixy="-5.7879E-10" ixz="-1.8543E-06" iyy="0.00030737" iyz="1.682E-12" izz="0.00019914"/>
    </inertial>
    <visual>
      <origin rpy="0 0 0" xyz="0 0 0"/>
      <geometry>
        <mesh filename="package://kmr_description/meshes/gripper/robotiq_85_base_link_fine.STL"/>
      </geometry>
      <material name="">
        <color rgba="0.1 0.1 0.1 1"/>
      </material>
    </visual>
    <collision>
      <origin rpy="0 0 0" xyz="0 0 0"/>
      <geometry>
        <mesh filename="package://kmr_description/meshes/gripper/robotiq_85_base_link_coarse.STL"/>
      </geometry>
    </collision>
  </link>
  <link name="gripper_left_outer_knuckle">
    <inertial>
      <origin rpy="0 0 0" xyz="0.0178331863169983 3.68915177224286E-11 0.0021442477325704"/>
      <mass value="0.00684838849434396"/>
      <inertia ixx="2.66832029033166E-07" ixy="1.66142314639824E-15" ixz="1.45945633322873E-07" iyy="1.3889233257419E-06" iyz="2.82951161241588E-15" izz="1.26603336914415E-06"/>
    </inertial>
    <visual>
      <origin rpy="0 0 0" xyz="0 0 0"/>
      <geometry>
        <mesh filename="package://kmr_description/meshes/gripper/outer_knuckle_fine.STL"/>
      </geometry>
      <material name="">
        <color rgba="0.1 0.1 0.1 1"/>
      </material>
    </visual>
    <collision>
      <origin rpy="0 0 0" xyz="0 0 0"/>
      <geometry>
        <mesh filename="package://kmr_description/meshes/gripper/outer_knuckle_coarse.STL"/>
      </geometry>
    </collision>
  </link>
  <joint name="gripper_finger_joint" type="revolute">
    <origin rpy="0 0 0" xyz="0.0306011444260539 0 0.0627920162695395"/>
    <parent link="gripper_base_link"/>
    <child link="gripper_left_outer_knuckle"/>
    <axis xyz="0 -1 0"/>
    <limit effort="1000" lower="0" upper="0.725" velocity="2.0"/>
  </joint>
  <link name="gripper_left_outer_finger">
    <inertial>
      <origin rpy="0 0 0" xyz="0.00131451599174296 2.88942057994543E-15 0.0215404163180413"/>
      <mass value="0.0273093985570947"/>
      <inertia ixx="8.51629628283022E-06" ixy="2.58174336207405E-19" ixz="3.83829504344079E-07" iyy="6.9133328065108E-06" iyz="-7.58589926143789E-19" izz="2.25006832221981E-06"/>
    </inertial>
    <visual>
      <origin rpy="0 0 0" xyz="0 0 0"/>
      <geometry>
        <mesh filename="package://kmr_description/meshes/gripper/outer_finger_fine.STL"/>
      </geometry>
      <material name="">
        <color rgba="0.1 0.1 0.1 1"/>
      </material>
    </visual>
    <collision>
      <origin rpy="0 0 0" xyz="0 0 0"/>
      <geometry>
        <mesh filename="package://kmr_description/meshes/gripper/outer_finger_coarse.STL"/>
      </geometry>
    </collision>
  </link>
  <joint name="gripper_left_outer_finger_joint" type="fixed">
    <origin rpy="0 0 0" xyz="0.0316910442266543 0 -0.00193396375724605"/>
    <parent link="gripper_left_outer_knuckle"/>
    <child link="gripper_left_outer_finger"/>
    <axis xyz="0 -1 0"/>
  </joint>
  <link name="gripper_left_inner_knuckle">
    <inertial>
      <origin rpy="0 0 0" xyz="0.017097546626628 -3.93808524389535E-10 0.0224918438201868"/>
      <mass value="0.0110930853895903"/>
      <inertia ixx="4.23392770691541E-06" ixy="5.748978936968E-15" ixz="1.78855677119788E-06" iyy="3.96548790524392E-06" iyz="1.05464666369669E-14" izz="3.24068002883007E-06"/>
    </inertial>
    <visual>
      <origin rpy="0 0 0" xyz="0 0 0"/>
      <geometry>
        <mesh filename="package://kmr_description/meshes/gripper/inner_knuckle_fine.STL"/>
      </geometry>
      <material name="">
        <color rgba="0.1 0.1 0.1 1"/>
      </material>
    </visual>
    <collision>
      <origin rpy="0 0 0" xyz="0 0 0"/>
      <geometry>
        <mesh filename="package://kmr_description/meshes/gripper/inner_knuckle_coarse.STL"/>
      </geometry>
    </collision>
  </link>
  <joint name="gripper_left_inner_knuckle_joint" type="revolute">
    <origin rpy="0 0 0" xyz="0.0127000000001501 0 0.0693074999999639"/>
    <parent link="gripper_base_link"/>
    <child link="gripper_left_inner_knuckle"/>
    <axis xyz="0 -1 0"/>
    <limit effort="1000" lower="0" upper="0.8757" velocity="2.0"/>
    <mimic joint="gripper_finger_joint" multiplier="1" offset="0"/>
  </joint>
  <link name="gripper_left_inner_finger">
    <inertial>
      <origin rpy="0 0 0" xyz="0.0060275613594574 -6.29183141465421E-15 0.00669925693133241"/>
      <mass value="0.00724255346165745"/>
      <inertia ixx="1.47824274053603E-06" ixy="-3.94884463570303E-19" ixz="-3.45268847648622E-07" iyy="1.70064480838395E-06" iyz="3.5059838910097E-19" izz="4.77151336838364E-07"/>
    </inertial>
    <visual>
      <origin rpy="0 0 0" xyz="0 0 0"/>
      <geometry>
        <mesh filename="package://kmr_description/meshes/gripper/inner_finger_fine.STL"/>
      </geometry>
      <material name="">
        <color rgba="0.1 0.1 0.1 1"/>
      </material>
    </visual>
    <collision>
      <origin rpy="0 0 0" xyz="0 0 0"/>
      <geometry>
        <mesh filename="package://kmr_description/meshes/gripper/inner_finger_coarse.STL"/>
      </geometry>
    </collision>
  </link>
  <joint name="gripper_left_inner_finger_joint" type="revolute">
    <origin rpy="0 0 0" xyz="0.034585310861294 0 0.0454970193817975"/>
    <parent link="gripper_left_inner_knuckle"/>
    <child link="gripper_left_inner_finger"/>
    <axis xyz="0 -1 0"/>
    <limit effort="1000" lower="0" upper="0.8757" velocity="2.0"/>
    <mimic joint="gripper_finger_joint" multiplier="-1" offset="0"/>
  </joint>
  <link name="gripper_right_inner_knuckle">
    <inertial>
      <origin rpy="0 0 0" xyz="0.0168606186773776 3.93808471820465E-10 0.0226699950793434"/>
      <mass value="0.0110930853895903"/>
      <inertia ixx="4.27134775939882E-06" ixy="-8.53568456728898E-15" ixz="1.77774229944246E-06" iyy="3.96548790524392E-06" iyz="-8.45108024914164E-15" izz="3.20325997634666E-06"/>
    </inertial>
    <visual>
      <origin rpy="0 0 0" xyz="0 0 0"/>
      <geometry>
        <mesh filename="package://kmr_description/meshes/gripper/inner_knuckle_fine.STL"/>
      </geometry>
      <material name="">
        <color rgba="0.1 0.1 0.1 1"/>
      </material>
    </visual>
    <collision>
      <origin rpy="0 0 0" xyz="0 0 0"/>
      <geometry>
        <mesh filename="package://kmr_description/meshes/gripper/inner_knuckle_coarse.STL"/>
      </geometry>
    </collision>
  </link>
  <joint name="gripper_right_inner_knuckle_joint" type="revolute">
    <origin rpy="0 0 3.14159265358979" xyz="-0.0126999999998499 0 0.0693075000000361"/>
    <parent link="gripper_base_link"/>
    <child link="gripper_right_inner_knuckle"/>
    <axis xyz="0 1 0"/>
    <limit effort="1000" lower="0" upper="0.8757" velocity="2.0"/>
    <mimic joint="gripper_finger_joint" multiplier="-1" offset="0"/>
  </joint>
  <link name="gripper_right_inner_finger">
    <inertial>
      <origin rpy="0 0 0" xyz="0.00602756228812038 -6.47284509480176E-15 0.00669925609578108"/>
      <mass value="0.00724255346165744"/>
      <inertia ixx="1.47824283625957E-06" ixy="-3.95952064019123E-19" ixz="-3.45268708875543E-07" iyy="1.70064480838394E-06" iyz="3.55286507960029E-19" izz="4.77151241114822E-07"/>
    </inertial>
    <visual>
      <origin rpy="0 0 0" xyz="0 0 0"/>
      <geometry>
        <mesh filename="package://kmr_description/meshes/gripper/inner_finger_fine.STL"/>
      </geometry>
      <material name="">
        <color rgba="0.1 0.1 0.1 1"/>
      </material>
    </visual>
    <collision>
      <origin rpy="0 0 0" xyz="0 0 0"/>
      <geometry>
        <mesh filename="package://kmr_description/meshes/gripper/inner_finger_coarse.STL"/>
      </geometry>
    </collision>
  </link>
  <joint name="gripper_right_inner_finger_joint" type="revolute">
    <origin rpy="0 0 0" xyz="0.0341060475457406 0 0.0458573878541688"/>
    <parent link="gripper_right_inner_knuckle"/>
    <child link="gripper_right_inner_finger"/>
    <axis xyz="0 1 0"/>
    <limit effort="1000" lower="0" upper="0.8757" velocity="2.0"/>
    <mimic joint="gripper_finger_joint" multiplier="1" offset="0"/>
  </joint>
  <link name="gripper_right_outer_knuckle">
    <inertial>
      <origin rpy="0 0 0" xyz="0.0178097074051638 3.60493211424024E-11 0.00233123458346721"/>
      <mass value="0.00684838849401352"/>
      <inertia ixx="2.70004361573169E-07" ixy="1.59579467624491E-15" ixz="1.56396493788199E-07" iyy="1.38892332558312E-06" iyz="2.82357800318817E-15" izz="1.26286103637978E-06"/>
    </inertial>
    <visual>
      <origin rpy="0 0 0" xyz="0 0 0"/>
      <geometry>
        <mesh filename="package://kmr_description/meshes/gripper/outer_knuckle_fine.STL"/>
      </geometry>
      <material name="">
        <color rgba="0.1 0.1 0.1 1"/>
      </material>
    </visual>
    <collision>
      <origin rpy="0 0 0" xyz="0 0 0"/>
      <geometry>
        <mesh filename="package://kmr_description/meshes/gripper/outer_knuckle_coarse.STL"/>
      </geometry>
    </collision>
  </link>
  <joint name="gripper_right_outer_knuckle_joint" type="revolute">
    <origin rpy="0 0 3.14159265358979" xyz="-0.0306011444258893 0 0.0627920162695395"/>
    <parent link="gripper_base_link"/>
    <child link="gripper_right_outer_knuckle"/>
    <axis xyz="0 1 0"/>
    <limit effort="1000" lower="0" upper="0.8757" velocity="2.0"/>
    <mimic joint="gripper_finger_joint" multiplier="-1" offset="0"/>
  </joint>
  <link name="gripper_right_outer_finger">
    <inertial>
      <origin rpy="0 0 0" xyz="0.00108844269639009 -2.611488350845E-15 0.0215530225245502"/>
      <mass value="0.0273093985570947"/>
      <inertia ixx="8.52366028592721E-06" ixy="3.41683380899422E-19" ixz="3.18003675694284E-07" iyy="6.91333280651081E-06" iyz="7.37726682706417E-19" izz="2.24270431912283E-06"/>
    </inertial>
    <visual>
      <origin rpy="0 0 0" xyz="0 0 0"/>
      <geometry>
        <mesh filename="package://kmr_description/meshes/gripper/outer_finger_fine.STL"/>
      </geometry>
      <material name="">
        <color rgba="0.1 0.1 0.1 1"/>
      </material>
    </visual>
    <collision>
      <origin rpy="0 0 0" xyz="0 0 0"/>
      <geometry>
        <mesh filename="package://kmr_description/meshes/gripper/outer_finger_coarse.STL"/>
      </geometry>
    </collision>
  </link>
  <joint name="gripper_right_outer_finger_joint" type="fixed">
    <origin rpy="0 0 0" xyz="0.0317095909367246 0 -0.0016013564954687"/>
    <parent link="gripper_right_outer_knuckle"/>
    <child link="gripper_right_outer_finger"/>
    <axis xyz="0 1 0"/>
  </joint>
  <!-- Manualy created joint and link to control end effector -->
  <joint name="gripper_center_joint" type="fixed">
    <origin rpy="0 0 0" xyz="0 0 0.1375"/>
    <parent link="gripper_base_link"/>
    <child link="gripper_center"/>
  </joint>
  <link name="gripper_center"/>
  <joint name="left_camera_adapter_joint" type="fixed">
    <origin rpy="0 0 0" xyz="0 0.275 0"/>
    <parent link="kmr_base_top_link"/>
    <child link="left_camera_adapter"/>
  </joint>
  <link name="left_camera_adapter">
    <visual>
      <origin rpy="0 0 0" xyz="0 0 0"/>
      <geometry>
        <box size="0.15 0.04 0.01"/>
      </geometry>
      <material name="aluminum"/>
    </visual>
  </link>
  <joint name="right_camera_adapter_joint" type="fixed">
    <origin rpy="0 0 0" xyz="0 -0.275 0"/>
    <parent link="kmr_base_top_link"/>
    <child link="right_camera_adapter"/>
  </joint>
  <link name="right_camera_adapter">
    <visual>
      <origin rpy="0 0 0" xyz="0 0 0"/>
      <geometry>
        <box size="0.15 0.04 0.01"/>
      </geometry>
      <material name="aluminum"/>
    </visual>
  </link>
  <!-- camera body, with origin at bottom screw mount -->
  <joint name="camera_left_joint" type="fixed">
    <origin rpy="0 0 1.5707963267948966" xyz="0 0 0.005"/>
    <parent link="left_camera_adapter"/>
    <child link="camera_left_bottom_screw_frame"/>
  </joint>
  <link name="camera_left_bottom_screw_frame"/>
  <joint name="camera_left_link_joint" type="fixed">
    <origin rpy="0 0 0" xyz="0.010600000000000002 0.0175 0.0125"/>
    <parent link="camera_left_bottom_screw_frame"/>
    <child link="camera_left_link"/>
  </joint>
  <link name="camera_left_link">
    <visual>
      <!-- the mesh origin is at front plate in between the two infrared camera axes -->
      <origin rpy="1.5707963267948966 0 1.5707963267948966" xyz="0.0043 -0.0175 0"/>
      <geometry>
        <mesh filename="package://kmr_description/meshes/d435/d435.dae"/>
      </geometry>
    </visual>
    <collision>
      <origin rpy="0 0 0" xyz="0 -0.0175 0"/>
      <geometry>
        <box size="0.02505 0.09 0.025"/>
      </geometry>
    </collision>
    <inertial>
      <!-- The following are not reliable values, and should not be used for modeling -->
      <mass value="0.072"/>
      <origin xyz="0 0 0"/>
      <inertia ixx="0.003881243" ixy="0.0" ixz="0.0" iyy="0.000498940" iyz="0.0" izz="0.003879257"/>
    </inertial>
  </link>
  <!-- camera depth joints and links -->
  <joint name="camera_left_depth_joint" type="fixed">
    <origin rpy="0 0 0" xyz="0 0 0"/>
    <parent link="camera_left_link"/>
    <child link="camera_left_depth_frame"/>
  </joint>
  <link name="camera_left_depth_frame"/>
  <joint name="camera_left_depth_optical_joint" type="fixed">
    <origin rpy="-1.5707963267948966 0 -1.5707963267948966" xyz="0 0 0"/>
    <parent link="camera_left_depth_frame"/>
    <child link="camera_left_depth_optical_frame"/>
  </joint>
  <link name="camera_left_depth_optical_frame"/>
  <!-- camera left IR joints and links -->
  <joint name="camera_left_infra1_joint" type="fixed">
    <origin rpy="0 0 0" xyz="0 0.0 0"/>
    <parent link="camera_left_link"/>
    <child link="camera_left_infra1_frame"/>
  </joint>
  <link name="camera_left_infra1_frame"/>
  <joint name="camera_left_infra1_optical_joint" type="fixed">
    <origin rpy="-1.5707963267948966 0 -1.5707963267948966" xyz="0 0 0"/>
    <parent link="camera_left_infra1_frame"/>
    <child link="camera_left_infra1_optical_frame"/>
  </joint>
  <link name="camera_left_infra1_optical_frame"/>
  <!-- camera right IR joints and links -->
  <joint name="camera_left_infra2_joint" type="fixed">
    <origin rpy="0 0 0" xyz="0 -0.05 0"/>
    <parent link="camera_left_link"/>
    <child link="camera_left_infra2_frame"/>
  </joint>
  <link name="camera_left_infra2_frame"/>
  <joint name="camera_left_infra2_optical_joint" type="fixed">
    <origin rpy="-1.5707963267948966 0 -1.5707963267948966" xyz="0 0 0"/>
    <parent link="camera_left_infra2_frame"/>
    <child link="camera_left_infra2_optical_frame"/>
  </joint>
  <link name="camera_left_infra2_optical_frame"/>
  <!-- camera color joints and links -->
  <joint name="camera_left_color_joint" type="fixed">
    <origin rpy="0 0 0" xyz="0 0.015 0"/>
    <parent link="camera_left_link"/>
    <child link="camera_left_color_frame"/>
  </joint>
  <link name="camera_left_color_frame"/>
  <joint name="camera_left_color_optical_joint" type="fixed">
    <origin rpy="-1.5707963267948966 0 -1.5707963267948966" xyz="0 0 0"/>
    <parent link="camera_left_color_frame"/>
    <child link="camera_left_color_optical_frame"/>
  </joint>
  <link name="camera_left_color_optical_frame"/>
  <!-- camera body, with origin at bottom screw mount -->
  <joint name="camera_right_joint" type="fixed">
    <origin rpy="0 0 -1.5707963267948966" xyz="0 0 0.005"/>
    <parent link="right_camera_adapter"/>
    <child link="camera_right_bottom_screw_frame"/>
  </joint>
  <link name="camera_right_bottom_screw_frame"/>
  <joint name="camera_right_link_joint" type="fixed">
    <origin rpy="0 0 0" xyz="0.010600000000000002 0.0175 0.0125"/>
    <parent link="camera_right_bottom_screw_frame"/>
    <child link="camera_right_link"/>
  </joint>
  <link name="camera_right_link">
    <visual>
      <!-- the mesh origin is at front plate in between the two infrared camera axes -->
      <origin rpy="1.5707963267948966 0 1.5707963267948966" xyz="0.0043 -0.0175 0"/>
      <geometry>
        <mesh filename="package://kmr_description/meshes/d435/d435.dae"/>
      </geometry>
    </visual>
    <collision>
      <origin rpy="0 0 0" xyz="0 -0.0175 0"/>
      <geometry>
        <box size="0.02505 0.09 0.025"/>
      </geometry>
    </collision>
    <inertial>
      <!-- The following are not reliable values, and should not be used for modeling -->
      <mass value="0.072"/>
      <origin xyz="0 0 0"/>
      <inertia ixx="0.003881243" ixy="0.0" ixz="0.0" iyy="0.000498940" iyz="0.0" izz="0.003879257"/>
    </inertial>
  </link>
  <!-- camera depth joints and links -->
  <joint name="camera_right_depth_joint" type="fixed">
    <origin rpy="0 0 0" xyz="0 0 0"/>
    <parent link="camera_right_link"/>
    <child link="camera_right_depth_frame"/>
  </joint>
  <link name="camera_right_depth_frame"/>
  <joint name="camera_right_depth_optical_joint" type="fixed">
    <origin rpy="-1.5707963267948966 0 -1.5707963267948966" xyz="0 0 0"/>
    <parent link="camera_right_depth_frame"/>
    <child link="camera_right_depth_optical_frame"/>
  </joint>
  <link name="camera_right_depth_optical_frame"/>
  <!-- camera left IR joints and links -->
  <joint name="camera_right_infra1_joint" type="fixed">
    <origin rpy="0 0 0" xyz="0 0.0 0"/>
    <parent link="camera_right_link"/>
    <child link="camera_right_infra1_frame"/>
  </joint>
  <link name="camera_right_infra1_frame"/>
  <joint name="camera_right_infra1_optical_joint" type="fixed">
    <origin rpy="-1.5707963267948966 0 -1.5707963267948966" xyz="0 0 0"/>
    <parent link="camera_right_infra1_frame"/>
    <child link="camera_right_infra1_optical_frame"/>
  </joint>
  <link name="camera_right_infra1_optical_frame"/>
  <!-- camera right IR joints and links -->
  <joint name="camera_right_infra2_joint" type="fixed">
    <origin rpy="0 0 0" xyz="0 -0.05 0"/>
    <parent link="camera_right_link"/>
    <child link="camera_right_infra2_frame"/>
  </joint>
  <link name="camera_right_infra2_frame"/>
  <joint name="camera_right_infra2_optical_joint" type="fixed">
    <origin rpy="-1.5707963267948966 0 -1.5707963267948966" xyz="0 0 0"/>
    <parent link="camera_right_infra2_frame"/>
    <child link="camera_right_infra2_optical_frame"/>
  </joint>
  <link name="camera_right_infra2_optical_frame"/>
  <!-- camera color joints and links -->
  <joint name="camera_right_color_joint" type="fixed">
    <origin rpy="0 0 0" xyz="0 0.015 0"/>
    <parent link="camera_right_link"/>
    <child link="camera_right_color_frame"/>
  </joint>
  <link name="camera_right_color_frame"/>
  <joint name="camera_right_color_optical_joint" type="fixed">
    <origin rpy="-1.5707963267948966 0 -1.5707963267948966" xyz="0 0 0"/>
    <parent link="camera_right_color_frame"/>
    <child link="camera_right_color_optical_frame"/>
  </joint>
  <link name="camera_right_color_optical_frame"/>
  <!-- camera body, with origin at bottom screw mount -->
  <joint name="camera_front_joint" type="fixed">
    <origin rpy="0 0 0" xyz="0.5 0 -0.0075"/>
    <parent link="kmr_base_top_link"/>
    <child link="camera_front_bottom_screw_frame"/>
  </joint>
  <link name="camera_front_bottom_screw_frame"/>
  <joint name="camera_front_link_joint" type="fixed">
    <origin rpy="0 0 0" xyz="0.010600000000000002 0.0175 0.0125"/>
    <parent link="camera_front_bottom_screw_frame"/>
    <child link="camera_front_link"/>
  </joint>
  <link name="camera_front_link">
    <visual>
      <!-- the mesh origin is at front plate in between the two infrared camera axes -->
      <origin rpy="1.5707963267948966 0 1.5707963267948966" xyz="0.0043 -0.0175 0"/>
      <geometry>
        <mesh filename="package://kmr_description/meshes/d435/d435.dae"/>
      </geometry>
    </visual>
    <collision>
      <origin rpy="0 0 0" xyz="0 -0.0175 0"/>
      <geometry>
        <box size="0.02505 0.09 0.025"/>
      </geometry>
    </collision>
    <inertial>
      <!-- The following are not reliable values, and should not be used for modeling -->
      <mass value="0.072"/>
      <origin xyz="0 0 0"/>
      <inertia ixx="0.003881243" ixy="0.0" ixz="0.0" iyy="0.000498940" iyz="0.0" izz="0.003879257"/>
    </inertial>
  </link>
  <!-- camera depth joints and links -->
  <joint name="camera_front_depth_joint" type="fixed">
    <origin rpy="0 0 0" xyz="0 0 0"/>
    <parent link="camera_front_link"/>
    <child link="camera_front_depth_frame"/>
  </joint>
  <link name="camera_front_depth_frame"/>
  <joint name="camera_front_depth_optical_joint" type="fixed">
    <origin rpy="-1.5707963267948966 0 -1.5707963267948966" xyz="0 0 0"/>
    <parent link="camera_front_depth_frame"/>
    <child link="camera_front_depth_optical_frame"/>
  </joint>
  <link name="camera_front_depth_optical_frame"/>
  <!-- camera left IR joints and links -->
  <joint name="camera_front_infra1_joint" type="fixed">
    <origin rpy="0 0 0" xyz="0 0.0 0"/>
    <parent link="camera_front_link"/>
    <child link="camera_front_infra1_frame"/>
  </joint>
  <link name="camera_front_infra1_frame"/>
  <joint name="camera_front_infra1_optical_joint" type="fixed">
    <origin rpy="-1.5707963267948966 0 -1.5707963267948966" xyz="0 0 0"/>
    <parent link="camera_front_infra1_frame"/>
    <child link="camera_front_infra1_optical_frame"/>
  </joint>
  <link name="camera_front_infra1_optical_frame"/>
  <!-- camera right IR joints and links -->
  <joint name="camera_front_infra2_joint" type="fixed">
    <origin rpy="0 0 0" xyz="0 -0.05 0"/>
    <parent link="camera_front_link"/>
    <child link="camera_front_infra2_frame"/>
  </joint>
  <link name="camera_front_infra2_frame"/>
  <joint name="camera_front_infra2_optical_joint" type="fixed">
    <origin rpy="-1.5707963267948966 0 -1.5707963267948966" xyz="0 0 0"/>
    <parent link="camera_front_infra2_frame"/>
    <child link="camera_front_infra2_optical_frame"/>
  </joint>
  <link name="camera_front_infra2_optical_frame"/>
  <!-- camera color joints and links -->
  <joint name="camera_front_color_joint" type="fixed">
    <origin rpy="0 0 0" xyz="0 0.015 0"/>
    <parent link="camera_front_link"/>
    <child link="camera_front_color_frame"/>
  </joint>
  <link name="camera_front_color_frame"/>
  <joint name="camera_front_color_optical_joint" type="fixed">
    <origin rpy="-1.5707963267948966 0 -1.5707963267948966" xyz="0 0 0"/>
    <parent link="camera_front_color_frame"/>
    <child link="camera_front_color_optical_frame"/>
  </joint>
  <link name="camera_front_color_optical_frame"/>
  <!-- camera body, with origin at bottom screw mount -->
  <joint name="camera_manipulator_joint" type="fixed">
    <origin rpy="0 -1.5707963267948966 -1.5707963267948966" xyz="0 0.035 0"/>
    <parent link="gripper_adapter"/>
    <child link="camera_manipulator_bottom_screw_frame"/>
  </joint>
  <link name="camera_manipulator_bottom_screw_frame"/>
  <joint name="camera_manipulator_link_joint" type="fixed">
    <origin rpy="0 0 0" xyz="0.010600000000000002 0.0175 0.0125"/>
    <parent link="camera_manipulator_bottom_screw_frame"/>
    <child link="camera_manipulator_link"/>
  </joint>
  <link name="camera_manipulator_link">
    <visual>
      <!-- the mesh origin is at front plate in between the two infrared camera axes -->
      <origin rpy="1.5707963267948966 0 1.5707963267948966" xyz="0.0043 -0.0175 0"/>
      <geometry>
        <mesh filename="package://kmr_description/meshes/d435/d435.dae"/>
      </geometry>
    </visual>
    <collision>
      <origin rpy="0 0 0" xyz="0 -0.0175 0"/>
      <geometry>
        <box size="0.02505 0.09 0.025"/>
      </geometry>
    </collision>
    <inertial>
      <!-- The following are not reliable values, and should not be used for modeling -->
      <mass value="0.072"/>
      <origin xyz="0 0 0"/>
      <inertia ixx="0.003881243" ixy="0.0" ixz="0.0" iyy="0.000498940" iyz="0.0" izz="0.003879257"/>
    </inertial>
  </link>
  <!-- camera depth joints and links -->
  <joint name="camera_manipulator_depth_joint" type="fixed">
    <origin rpy="0 0 0" xyz="0 0 0"/>
    <parent link="camera_manipulator_link"/>
    <child link="camera_manipulator_depth_frame"/>
  </joint>
  <link name="camera_manipulator_depth_frame"/>
  <joint name="camera_manipulator_depth_optical_joint" type="fixed">
    <origin rpy="-1.5707963267948966 0 -1.5707963267948966" xyz="0 0 0"/>
    <parent link="camera_manipulator_depth_frame"/>
    <child link="camera_manipulator_depth_optical_frame"/>
  </joint>
  <link name="camera_manipulator_depth_optical_frame"/>
  <!-- camera left IR joints and links -->
  <joint name="camera_manipulator_infra1_joint" type="fixed">
    <origin rpy="0 0 0" xyz="0 0.0 0"/>
    <parent link="camera_manipulator_link"/>
    <child link="camera_manipulator_infra1_frame"/>
  </joint>
  <link name="camera_manipulator_infra1_frame"/>
  <joint name="camera_manipulator_infra1_optical_joint" type="fixed">
    <origin rpy="-1.5707963267948966 0 -1.5707963267948966" xyz="0 0 0"/>
    <parent link="camera_manipulator_infra1_frame"/>
    <child link="camera_manipulator_infra1_optical_frame"/>
  </joint>
  <link name="camera_manipulator_infra1_optical_frame"/>
  <!-- camera right IR joints and links -->
  <joint name="camera_manipulator_infra2_joint" type="fixed">
    <origin rpy="0 0 0" xyz="0 -0.05 0"/>
    <parent link="camera_manipulator_link"/>
    <child link="camera_manipulator_infra2_frame"/>
  </joint>
  <link name="camera_manipulator_infra2_frame"/>
  <joint name="camera_manipulator_infra2_optical_joint" type="fixed">
    <origin rpy="-1.5707963267948966 0 -1.5707963267948966" xyz="0 0 0"/>
    <parent link="camera_manipulator_infra2_frame"/>
    <child link="camera_manipulator_infra2_optical_frame"/>
  </joint>
  <link name="camera_manipulator_infra2_optical_frame"/>
  <!-- camera color joints and links -->
  <joint name="camera_manipulator_color_joint" type="fixed">
    <origin rpy="0 0 0" xyz="0 0.015 0"/>
    <parent link="camera_manipulator_link"/>
    <child link="camera_manipulator_color_frame"/>
  </joint>
  <link name="camera_manipulator_color_frame"/>
  <joint name="camera_manipulator_color_optical_joint" type="fixed">
    <origin rpy="-1.5707963267948966 0 -1.5707963267948966" xyz="0 0 0"/>
    <parent link="camera_manipulator_color_frame"/>
    <child link="camera_manipulator_color_optical_frame"/>
  </joint>
  <link name="camera_manipulator_color_optical_frame"/>
</robot>
